Workbook

Sheet Lucros aos Sócios
A1: Código | B1: CNPJ | C1: Razão Social | D1: Tipo de Aferiação | E1: CPF / CNPJ | F1: Sócios | G1: Participação | H1: Lucros Distribuídos
A2: 106 | B2: =VLOOKUP(A2,Empresas!A:B,2,0) -> 04.431.460/0001-25 | C2: =VLOOKUP(B2,Empresas!B:C,2,0) -> 04.431.460 Ramiro Duenas Aranzabal | D2: =VLOOKUP(C2,'[1]Controle Distribuição de Lucros'!$C$1:$G$357,5,0) -> #N/A | E2: 217.925.868-25 | F2: Ramiro DuenasAranzal | G2: 1 | H2: =IF(D2="Contabilidade Aproximada",(VLOOKUP(C2,'Apuração Contabilidade Aproxima'!$C$1:$M$357,11,0)*G2),IF(D2="Distribuição por Presunção",(VLOOKUP(C2,'[1]Controle Distribuição de Lucros'!$C$1:$Q$357,15)*'Lucros aos Sócios'!G2),IF(D2="Contabilidade"," ",0))) -> #N/A
A3: 119 | B3: =VLOOKUP(A3,Empresas!A:B,2,0) -> 27.541.980/0001-96 | C3: =VLOOKUP(B3,Empresas!B:C,2,0) -> 4.Com Serviços Empresariais Ltda | D3: =VLOOKUP(C3,'[1]Controle Distribuição de Lucros'!$C$1:$G$357,5,0) -> #N/A | E3: 945.266.568-87 | F3: Milton Munhoz | G3: 0.5 | H3: =IF(D3="Contabilidade Aproximada",(VLOOKUP(C3,'Apuração Contabilidade Aproxima'!$C$1:$M$357,11,0)*G3),IF(D3="Distribuição por Presunção",(VLOOKUP(C3,'[1]Controle Distribuição de Lucros'!$C$1:$Q$357,15)*'Lucros aos Sócios'!G3),IF(D3="Contabilidade"," ",0))) -> #N/A
A4: 119 | B4: =VLOOKUP(A4,Empresas!A:B,2,0) -> 27.541.980/0001-96 | C4: =VLOOKUP(B4,Empresas!B:C,2,0) -> 4.Com Serviços Empresariais Ltda | D4: =VLOOKUP(C4,'[1]Controle Distribuição de Lucros'!$C$1:$G$357,5,0) -> #N/A | E4: 033.786.148-03 | F4: Selma Maria de Avellar | G4: 0.5 | H4: =IF(D4="Contabilidade Aproximada",(VLOOKUP(C4,'Apuração Contabilidade Aproxima'!$C$1:$M$357,11,0)*G4),IF(D4="Distribuição por Presunção",(VLOOKUP(C4,'[1]Controle Distribuição de Lucros'!$C$1:$Q$357,15)*'Lucros aos Sócios'!G4),IF(D4="Contabilidade"," ",0))) -> #N/A
A5: 415 | B5: =VLOOKUP(A5,Empresas!A:B,2,0) -> 42.360.609/0001-11 | C5: =VLOOKUP(B5,Empresas!B:C,2,0) -> 42.360.609 Dener Mendonça de Souza | D5: =VLOOKUP(C5,'[1]Controle Distribuição de Lucros'!$C$1:$G$357,5,0) -> #N/A | E5: 359.623.988-58 | F5: Dener Mendonca de Souza | G5: 1 | H5: =IF(D5="Contabilidade Aproximada",(VLOOKUP(C5,'Apuração Contabilidade Aproxima'!$C$1:$M$357,11,0)*G5),IF(D5="Distribuição por Presunção",(VLOOKUP(C5,'[1]Controle Distribuição de Lucros'!$C$1:$Q$357,15)*'Lucros aos Sócios'!G5),IF(D5="Contabilidade"," ",0))) -> #N/A
A6: 218 | B6: =VLOOKUP(A6,Empresas!A:B,2,0) -> 43.436.474/0001-93 | C6: =VLOOKUP(B6,Empresas!B:C,2,0) -> 43.436.474 Maria Clara Tomé Garcia | D6: =VLOOKUP(C6,'[1]Controle Distribuição de Lucros'!$C$1:$G$357,5,0) -> #N/A | E6: 390.807.018-07 | F6: Maria Clara Tome Garcia | G6: 1 | H6: =IF(D6="Contabilidade Aproximada",(VLOOKUP(C6,'Apuração Contabilidade Aproxima'!$C$1:$M$357,11,0)*G6),IF(D6="Distribuição por Presunção",(VLOOKUP(C6,'[1]Controle Distribuição de Lucros'!$C$1:$Q$357,15)*'Lucros aos Sócios'!G6),IF(D6="Contabilidade"," ",0))) -> #N/A
A7: 628 | B7: =VLOOKUP(A7,Empresas!A:B,2,0) -> 43.959.791/0001-94 | C7: =VLOOKUP(B7,Empresas!B:C,2,0) -> 43.959.791 Ana Isabela Pithan Maraschin | D7: =VLOOKUP(C7,'[1]Controle Distribuição de Lucros'!$C$1:$G$357,5,0) -> #N/A | E7: 060.646.018-76 | F7: Ana Isabela Pithan Maraschin | G7: 1 | H7: =IF(D7="Contabilidade Aproximada",(VLOOKUP(C7,'Apuração Contabilidade Aproxima'!$C$1:$M$357,11,0)*G7),IF(D7="Distribuição por Presunção",(VLOOKUP(C7,'[1]Controle Distribuição de Lucros'!$C$1:$Q$357,15)*'Lucros aos Sócios'!G7),IF(D7="Contabilidade"," ",0))) -> #N/A
A8: 227 | B8: =VLOOKUP(A8,Empresas!A:B,2,0) -> 44.645.259/0001-65 | C8: =VLOOKUP(B8,Empresas!B:C,2,0) -> 44.645.259 Rebeca Brito Cardoso | D8: =VLOOKUP(C8,'[1]Controle Distribuição de Lucros'!$C$1:$G$357,5,0) -> #N/A | E8: 416.773.648-90 | F8: Rebeca Brito Cardoso | G8: 1 | H8: =IF(D8="Contabilidade Aproximada",(VLOOKUP(C8,'Apuração Contabilidade Aproxima'!$C$1:$M$357,11,0)*G8),IF(D8="Distribuição por Presunção",(VLOOKUP(C8,'[1]Controle Distribuição de Lucros'!$C$1:$Q$357,15)*'Lucros aos Sócios'!G8),IF(D8="Contabilidade"," ",0))) -> #N/A
A9: 359 | B9: =VLOOKUP(A9,Empresas!A:B,2,0) -> 04.362.429/0001-80 | C9: =VLOOKUP(B9,Empresas!B:C,2,0) -> 4CS Serviços Ltda | D9: =VLOOKUP(C9,'[1]Controle Distribuição de Lucros'!$C$1:$G$357,5,0) -> #N/A | E9: 373.682.718-00 | F9: Daniel Gomes Pereira Assunção | G9: 1 | H9: =IF(D9="Contabilidade Aproximada",(VLOOKUP(C9,'Apuração Contabilidade Aproxima'!$C$1:$M$357,11,0)*G9),IF(D9="Distribuição por Presunção",(VLOOKUP(C9,'[1]Controle Distribuição de Lucros'!$C$1:$Q$357,15)*'Lucros aos Sócios'!G9),IF(D9="Contabilidade"," ",0))) -> #N/A
A10: 638 | B10: =VLOOKUP(A10,Empresas!A:B,2,0) -> 51.957.545/0001-21 | C10: =VLOOKUP(B10,Empresas!B:C,2,0) -> 51.957.545 Marjorie Abdallah | D10: =VLOOKUP(C10,'[1]Controle Distribuição de Lucros'!$C$1:$G$357,5,0) -> #N/A | E10: 44728556824 | F10: Marjorie Abdallah | G10: 1 | H10: =IF(D10="Contabilidade Aproximada",(VLOOKUP(C10,'Apuração Contabilidade Aproxima'!$C$1:$M$357,11,0)*G10),IF(D10="Distribuição por Presunção",(VLOOKUP(C10,'[1]Controle Distribuição de Lucros'!$C$1:$Q$357,15)*'Lucros aos Sócios'!G10),IF(D10="Contabilidade"," ",0))) -> #N/A
A11: 437 | B11: =VLOOKUP(A11,Empresas!A:B,2,0) -> 53.494.930/0001-05 | C11: =VLOOKUP(B11,Empresas!B:C,2,0) -> 53.494.930 Gabriela Afonso Prado | D11: =VLOOKUP(C11,'[1]Controle Distribuição de Lucros'!$C$1:$G$357,5,0) -> #N/A | E11: 855.893.301-49 | F11: Gabriela Afonso Prado | G11: 1 | H11: =IF(D11="Contabilidade Aproximada",(VLOOKUP(C11,'Apuração Contabilidade Aproxima'!$C$1:$M$357,11,0)*G11),IF(D11="Distribuição por Presunção",(VLOOKUP(C11,'[1]Controle Distribuição de Lucros'!$C$1:$Q$357,15)*'Lucros aos Sócios'!G11),IF(D11="Contabilidade"," ",0))) -> #N/A
A12: 461 | B12: =VLOOKUP(A12,Empresas!A:B,2,0) -> 54.535.015/0001-83 | C12: =VLOOKUP(B12,Empresas!B:C,2,0) -> Ada Maria Fraulo Pires | D12: =VLOOKUP(C12,'[1]Controle Distribuição de Lucros'!$C$1:$G$357,5,0) -> #N/A | E12: 297.312.228-71 | F12: Ada Maria Fraulo Pires | G12: 1 | H12: =IF(D12="Contabilidade Aproximada",(VLOOKUP(C12,'Apuração Contabilidade Aproxima'!$C$1:$M$357,11,0)*G12),IF(D12="Distribuição por Presunção",(VLOOKUP(C12,'[1]Controle Distribuição de Lucros'!$C$1:$Q$357,15)*'Lucros aos Sócios'!G12),IF(D12="Contabilidade"," ",0))) -> #N/A
A13: 525 | B13: =VLOOKUP(A13,Empresas!A:B,2,0) -> 58.344.129/0001-05 | C13: =VLOOKUP(B13,Empresas!B:C,2,0) -> 58.344.129 Gilda Maria de Lima Roberto | D13: =VLOOKUP(C13,'[1]Controle Distribuição de Lucros'!$C$1:$G$357,5,0) -> #N/A | E13: 270.967.878-01 | F13: Gilda Maria de Lima Roberto | G13: 1 | H13: =IF(D13="Contabilidade Aproximada",(VLOOKUP(C13,'Apuração Contabilidade Aproxima'!$C$1:$M$357,11,0)*G13),IF(D13="Distribuição por Presunção",(VLOOKUP(C13,'[1]Controle Distribuição de Lucros'!$C$1:$Q$357,15)*'Lucros aos Sócios'!G13),IF(D13="Contabilidade"," ",0))) -> #N/A
A14: 608 | B14: =VLOOKUP(A14,Empresas!A:B,2,0) -> 13.581.219/0001-73 | C14: =VLOOKUP(B14,Empresas!B:C,2,0) -> A & V Marques Imóveis Ltda | D14: =VLOOKUP(C14,'[1]Controle Distribuição de Lucros'!$C$1:$G$357,5,0) -> #N/A | E14: 29477113867 | F14: Vagner Luis Marques | G14: 1 | H14: =IF(D14="Contabilidade Aproximada",(VLOOKUP(C14,'Apuração Contabilidade Aproxima'!$C$1:$M$357,11,0)*G14),IF(D14="Distribuição por Presunção",(VLOOKUP(C14,'[1]Controle Distribuição de Lucros'!$C$1:$Q$357,15)*'Lucros aos Sócios'!G14),IF(D14="Contabilidade"," ",0))) -> #N/A
A15: 34 | B15: =VLOOKUP(A15,Empresas!A:B,2,0) -> 22.189.167/0001-85 | C15: =VLOOKUP(B15,Empresas!B:C,2,0) -> A Galeria Artes Presentes Jóias Design Rocym Ltda | D15: =VLOOKUP(C15,'[1]Controle Distribuição de Lucros'!$C$1:$G$357,5,0) -> #N/A | E15: 082.807.148-98 | F15: Ronaldo Szaniecki | G15: 1 | H15: =IF(D15="Contabilidade Aproximada",(VLOOKUP(C15,'Apuração Contabilidade Aproxima'!$C$1:$M$357,11,0)*G15),IF(D15="Distribuição por Presunção",(VLOOKUP(C15,'[1]Controle Distribuição de Lucros'!$C$1:$Q$357,15)*'Lucros aos Sócios'!G15),IF(D15="Contabilidade"," ",0))) -> #N/A
A16: 523 | B16: =VLOOKUP(A16,Empresas!A:B,2,0) -> 11.360.241/0001-68 | C16: =VLOOKUP(B16,Empresas!B:C,2,0) -> A. de S. Cafcalas | D16: =VLOOKUP(C16,'[1]Controle Distribuição de Lucros'!$C$1:$G$357,5,0) -> #N/A | E16: 24787045873 | F16: Alexandre de Siqueira Cafcalas | G16: 1 | H16: =IF(D16="Contabilidade Aproximada",(VLOOKUP(C16,'Apuração Contabilidade Aproxima'!$C$1:$M$357,11,0)*G16),IF(D16="Distribuição por Presunção",(VLOOKUP(C16,'[1]Controle Distribuição de Lucros'!$C$1:$Q$357,15)*'Lucros aos Sócios'!G16),IF(D16="Contabilidade"," ",0))) -> #N/A
A17: 587 | B17: =VLOOKUP(A17,Empresas!A:B,2,0) -> 61.203.201/0001-80 | C17: =VLOOKUP(B17,Empresas!B:C,2,0) -> A2M Ltda | D17: =VLOOKUP(C17,'[1]Controle Distribuição de Lucros'!$C$1:$G$357,5,0) -> #N/A | E17: 51229283803 | F17: Fred Ades | G17: 0.5 | H17: =IF(D17="Contabilidade Aproximada",(VLOOKUP(C17,'Apuração Contabilidade Aproxima'!$C$1:$M$357,11,0)*G17),IF(D17="Distribuição por Presunção",(VLOOKUP(C17,'[1]Controle Distribuição de Lucros'!$C$1:$Q$357,15)*'Lucros aos Sócios'!G17),IF(D17="Contabilidade"," ",0))) -> #N/A
A18: 587 | B18: =VLOOKUP(A18,Empresas!A:B,2,0) -> 61.203.201/0001-80 | C18: =VLOOKUP(B18,Empresas!B:C,2,0) -> A2M Ltda | D18: =VLOOKUP(C18,'[1]Controle Distribuição de Lucros'!$C$1:$G$357,5,0) -> #N/A | E18: 50195368819 | F18: Jean Richard Mansur | G18: 0.5 | H18: =IF(D18="Contabilidade Aproximada",(VLOOKUP(C18,'Apuração Contabilidade Aproxima'!$C$1:$M$357,11,0)*G18),IF(D18="Distribuição por Presunção",(VLOOKUP(C18,'[1]Controle Distribuição de Lucros'!$C$1:$Q$357,15)*'Lucros aos Sócios'!G18),IF(D18="Contabilidade"," ",0))) -> #N/A
A19: 225 | B19: =VLOOKUP(A19,Empresas!A:B,2,0) -> 04.438.239/0001-07 | C19: =VLOOKUP(B19,Empresas!B:C,2,0) -> AGM Representações Comerciais Ltda | D19: =VLOOKUP(C19,'[1]Controle Distribuição de Lucros'!$C$1:$G$357,5,0) -> #N/A | E19: 29351733840 | F19: Andre Berti Sampaio Xavier | G19: 0.93 | H19: =IF(D19="Contabilidade Aproximada",(VLOOKUP(C19,'Apuração Contabilidade Aproxima'!$C$1:$M$357,11,0)*G19),IF(D19="Distribuição por Presunção",(VLOOKUP(C19,'[1]Controle Distribuição de Lucros'!$C$1:$Q$357,15)*'Lucros aos Sócios'!G19),IF(D19="Contabilidade"," ",0))) -> #N/A
A20: 225 | B20: =VLOOKUP(A20,Empresas!A:B,2,0) -> 04.438.239/0001-07 | C20: =VLOOKUP(B20,Empresas!B:C,2,0) -> AGM Representações Comerciais Ltda | D20: =VLOOKUP(C20,'[1]Controle Distribuição de Lucros'!$C$1:$G$357,5,0) -> #N/A | E20: 30502745819 | F20: Fernanda Diniz Silva | G20: 0.07 | H20: =IF(D20="Contabilidade Aproximada",(VLOOKUP(C20,'Apuração Contabilidade Aproxima'!$C$1:$M$357,11,0)*G20),IF(D20="Distribuição por Presunção",(VLOOKUP(C20,'[1]Controle Distribuição de Lucros'!$C$1:$Q$357,15)*'Lucros aos Sócios'!G20),IF(D20="Contabilidade"," ",0))) -> #N/A
A21: 572 | B21: =VLOOKUP(A21,Empresas!A:B,2,0) -> 44.114.755/0001-92 | C21: =VLOOKUP(B21,Empresas!B:C,2,0) -> AGR Tubos Conexões e Válvulas Ltda | D21: =VLOOKUP(C21,'[1]Controle Distribuição de Lucros'!$C$1:$G$357,5,0) -> #N/A | E21: 333.804.098-98 | F21: Francisca Regis da Silva | G21: 1 | H21: =IF(D21="Contabilidade Aproximada",(VLOOKUP(C21,'Apuração Contabilidade Aproxima'!$C$1:$M$357,11,0)*G21),IF(D21="Distribuição por Presunção",(VLOOKUP(C21,'[1]Controle Distribuição de Lucros'!$C$1:$Q$357,15)*'Lucros aos Sócios'!G21),IF(D21="Contabilidade"," ",0))) -> #N/A
A22: 597 | B22: =VLOOKUP(A22,Empresas!A:B,2,0) -> 33.023.255/0001-29 | C22: =VLOOKUP(B22,Empresas!B:C,2,0) -> Alan W de O Lima Tecnologia da Informação | D22: =VLOOKUP(C22,'[1]Controle Distribuição de Lucros'!$C$1:$G$357,5,0) -> #N/A | E22: 281.763.258-30 | F22: Alan William de Oliveira Lima | G22: 1 | H22: =IF(D22="Contabilidade Aproximada",(VLOOKUP(C22,'Apuração Contabilidade Aproxima'!$C$1:$M$357,11,0)*G22),IF(D22="Distribuição por Presunção",(VLOOKUP(C22,'[1]Controle Distribuição de Lucros'!$C$1:$Q$357,15)*'Lucros aos Sócios'!G22),IF(D22="Contabilidade"," ",0))) -> #N/A
A23: 617 | B23: =VLOOKUP(A23,Empresas!A:B,2,0) -> 58.717.889/0001-02 | C23: =VLOOKUP(B23,Empresas!B:C,2,0) -> Ale Holding Participações e Negócios Ltda | D23: =VLOOKUP(C23,'[1]Controle Distribuição de Lucros'!$C$1:$G$357,5,0) -> #N/A | E23: 395.549.548-59 | F23: Luis Henrique Ale Cezar | G23: 1 | H23: =IF(D23="Contabilidade Aproximada",(VLOOKUP(C23,'Apuração Contabilidade Aproxima'!$C$1:$M$357,11,0)*G23),IF(D23="Distribuição por Presunção",(VLOOKUP(C23,'[1]Controle Distribuição de Lucros'!$C$1:$Q$357,15)*'Lucros aos Sócios'!G23),IF(D23="Contabilidade"," ",0))) -> #N/A
A24: 303 | B24: =VLOOKUP(A24,Empresas!A:B,2,0) -> 02.864.188/0001-41 | C24: =VLOOKUP(B24,Empresas!B:C,2,0) -> Alexandre Sgreccia | D24: =VLOOKUP(C24,'[1]Controle Distribuição de Lucros'!$C$1:$G$357,5,0) -> #N/A | E24: 528.843.098-53 | F24: Alexandre Sgreccia | G24: 1 | H24: =IF(D24="Contabilidade Aproximada",(VLOOKUP(C24,'Apuração Contabilidade Aproxima'!$C$1:$M$357,11,0)*G24),IF(D24="Distribuição por Presunção",(VLOOKUP(C24,'[1]Controle Distribuição de Lucros'!$C$1:$Q$357,15)*'Lucros aos Sócios'!G24),IF(D24="Contabilidade"," ",0))) -> #N/A
A25: 230 | B25: =VLOOKUP(A25,Empresas!A:B,2,0) -> 04.746.127/0001-05 | C25: =VLOOKUP(B25,Empresas!B:C,2,0) -> Alexandre Silva Voza | D25: =VLOOKUP(C25,'[1]Controle Distribuição de Lucros'!$C$1:$G$357,5,0) -> #N/A | E25: 12558085867 | F25: Alexandre Silva Voza | G25: 1 | H25: =IF(D25="Contabilidade Aproximada",(VLOOKUP(C25,'Apuração Contabilidade Aproxima'!$C$1:$M$357,11,0)*G25),IF(D25="Distribuição por Presunção",(VLOOKUP(C25,'[1]Controle Distribuição de Lucros'!$C$1:$Q$357,15)*'Lucros aos Sócios'!G25),IF(D25="Contabilidade"," ",0))) -> #N/A
A26: 370 | B26: =VLOOKUP(A26,Empresas!A:B,2,0) -> 37.140.411/0001-92 | C26: =VLOOKUP(B26,Empresas!B:C,2,0) -> Allora Construtora e Incorporadora Ltda | D26: =VLOOKUP(C26,'[1]Controle Distribuição de Lucros'!$C$1:$G$357,5,0) -> #N/A | E26: 870.580.144-34 | F26: Gustavo Lopes Berard | G26: 1 | H26: =IF(D26="Contabilidade Aproximada",(VLOOKUP(C26,'Apuração Contabilidade Aproxima'!$C$1:$M$357,11,0)*G26),IF(D26="Distribuição por Presunção",(VLOOKUP(C26,'[1]Controle Distribuição de Lucros'!$C$1:$Q$357,15)*'Lucros aos Sócios'!G26),IF(D26="Contabilidade"," ",0))) -> #N/A
A27: 578 | B27: =VLOOKUP(A27,Empresas!A:B,2,0) -> 13.314.231/0001-11 | C27: =VLOOKUP(B27,Empresas!B:C,2,0) -> Alpha Entretenimento e Lazer Ltda | D27: =VLOOKUP(C27,'[1]Controle Distribuição de Lucros'!$C$1:$G$357,5,0) -> #N/A | E27: 269.649.348-04 | F27: João Aprobato Neto | G27: 0.7 | H27: =IF(D27="Contabilidade Aproximada",(VLOOKUP(C27,'Apuração Contabilidade Aproxima'!$C$1:$M$357,11,0)*G27),IF(D27="Distribuição por Presunção",(VLOOKUP(C27,'[1]Controle Distribuição de Lucros'!$C$1:$Q$357,15)*'Lucros aos Sócios'!G27),IF(D27="Contabilidade"," ",0))) -> #N/A
A28: 578 | B28: =VLOOKUP(A28,Empresas!A:B,2,0) -> 13.314.231/0001-11 | C28: =VLOOKUP(B28,Empresas!B:C,2,0) -> Alpha Entretenimento e Lazer Ltda | D28: =VLOOKUP(C28,'[1]Controle Distribuição de Lucros'!$C$1:$G$357,5,0) -> #N/A | E28: 285.321.248-36 | F28: Flaviane Gomes Assunção Aprobato | G28: 0.3 | H28: =IF(D28="Contabilidade Aproximada",(VLOOKUP(C28,'Apuração Contabilidade Aproxima'!$C$1:$M$357,11,0)*G28),IF(D28="Distribuição por Presunção",(VLOOKUP(C28,'[1]Controle Distribuição de Lucros'!$C$1:$Q$357,15)*'Lucros aos Sócios'!G28),IF(D28="Contabilidade"," ",0))) -> #N/A
A29: 302 | B29: =VLOOKUP(A29,Empresas!A:B,2,0) -> 01.665.434/0001-73 | C29: =VLOOKUP(B29,Empresas!B:C,2,0) -> Alphaville Comercial Ltda | D29: =VLOOKUP(C29,'[1]Controle Distribuição de Lucros'!$C$1:$G$357,5,0) -> #N/A | E29: 14843851876 | F29: Fabiana Romani Vieira | G29: 0.5 | H29: =IF(D29="Contabilidade Aproximada",(VLOOKUP(C29,'Apuração Contabilidade Aproxima'!$C$1:$M$357,11,0)*G29),IF(D29="Distribuição por Presunção",(VLOOKUP(C29,'[1]Controle Distribuição de Lucros'!$C$1:$Q$357,15)*'Lucros aos Sócios'!G29),IF(D29="Contabilidade"," ",0))) -> #N/A
A30: 302 | B30: =VLOOKUP(A30,Empresas!A:B,2,0) -> 01.665.434/0001-73 | C30: =VLOOKUP(B30,Empresas!B:C,2,0) -> Alphaville Comercial Ltda | D30: =VLOOKUP(C30,'[1]Controle Distribuição de Lucros'!$C$1:$G$357,5,0) -> #N/A | E30: 16505634851 | F30: Luis Gustavo Ozorio Valentim | G30: 0.5 | H30: =IF(D30="Contabilidade Aproximada",(VLOOKUP(C30,'Apuração Contabilidade Aproxima'!$C$1:$M$357,11,0)*G30),IF(D30="Distribuição por Presunção",(VLOOKUP(C30,'[1]Controle Distribuição de Lucros'!$C$1:$Q$357,15)*'Lucros aos Sócios'!G30),IF(D30="Contabilidade"," ",0))) -> #N/A
A31: 376 | B31: =VLOOKUP(A31,Empresas!A:B,2,0) -> 09.086.104/0001-35 | C31: =VLOOKUP(B31,Empresas!B:C,2,0) -> Américo Suriano e Companhia Ltda | D31: =VLOOKUP(C31,'[1]Controle Distribuição de Lucros'!$C$1:$G$357,5,0) -> #N/A | E31: 069.248.158-39 | F31: Americo Suriano Neto | G31: 0.9998 | H31: =IF(D31="Contabilidade Aproximada",(VLOOKUP(C31,'Apuração Contabilidade Aproxima'!$C$1:$M$357,11,0)*G31),IF(D31="Distribuição por Presunção",(VLOOKUP(C31,'[1]Controle Distribuição de Lucros'!$C$1:$Q$357,15)*'Lucros aos Sócios'!G31),IF(D31="Contabilidade"," ",0))) -> #N/A
A32: 376 | B32: =VLOOKUP(A32,Empresas!A:B,2,0) -> 09.086.104/0001-35 | C32: =VLOOKUP(B32,Empresas!B:C,2,0) -> Américo Suriano e Companhia Ltda | D32: =VLOOKUP(C32,'[1]Controle Distribuição de Lucros'!$C$1:$G$357,5,0) -> #N/A | E32: 319.004.148-21 | F32: Michelle de Lacerda Castor | G32: 0.0001 | H32: =IF(D32="Contabilidade Aproximada",(VLOOKUP(C32,'Apuração Contabilidade Aproxima'!$C$1:$M$357,11,0)*G32),IF(D32="Distribuição por Presunção",(VLOOKUP(C32,'[1]Controle Distribuição de Lucros'!$C$1:$Q$357,15)*'Lucros aos Sócios'!G32),IF(D32="Contabilidade"," ",0))) -> #N/A
A33: 376 | B33: =VLOOKUP(A33,Empresas!A:B,2,0) -> 09.086.104/0001-35 | C33: =VLOOKUP(B33,Empresas!B:C,2,0) -> Américo Suriano e Companhia Ltda | D33: =VLOOKUP(C33,'[1]Controle Distribuição de Lucros'!$C$1:$G$357,5,0) -> #N/A | E33: 368.579.708-58 | F33: Monica Lacerda Suriano | G33: 0.0001 | H33: =IF(D33="Contabilidade Aproximada",(VLOOKUP(C33,'Apuração Contabilidade Aproxima'!$C$1:$M$357,11,0)*G33),IF(D33="Distribuição por Presunção",(VLOOKUP(C33,'[1]Controle Distribuição de Lucros'!$C$1:$Q$357,15)*'Lucros aos Sócios'!G33),IF(D33="Contabilidade"," ",0))) -> #N/A
A34: 576 | B34: =VLOOKUP(A34,Empresas!A:B,2,0) -> 49.343.692/0001-60 | C34: =VLOOKUP(B34,Empresas!B:C,2,0) -> Ápice Artes Gráficas Ltda | D34: =VLOOKUP(C34,'[1]Controle Distribuição de Lucros'!$C$1:$G$357,5,0) -> #N/A | E34: 039.267.368-10 | F34: Anna Lia Grandi Wosniak | G34: 0.334 | H34: =IF(D34="Contabilidade Aproximada",(VLOOKUP(C34,'Apuração Contabilidade Aproxima'!$C$1:$M$357,11,0)*G34),IF(D34="Distribuição por Presunção",(VLOOKUP(C34,'[1]Controle Distribuição de Lucros'!$C$1:$Q$357,15)*'Lucros aos Sócios'!G34),IF(D34="Contabilidade"," ",0))) -> #N/A
A35: 576 | B35: =VLOOKUP(A35,Empresas!A:B,2,0) -> 49.343.692/0001-60 | C35: =VLOOKUP(B35,Empresas!B:C,2,0) -> Ápice Artes Gráficas Ltda | D35: =VLOOKUP(C35,'[1]Controle Distribuição de Lucros'!$C$1:$G$357,5,0) -> #N/A | E35: 878.137.778-91 | F35: Reinaldo Wosniak | G35: 0.666 | H35: =IF(D35="Contabilidade Aproximada",(VLOOKUP(C35,'Apuração Contabilidade Aproxima'!$C$1:$M$357,11,0)*G35),IF(D35="Distribuição por Presunção",(VLOOKUP(C35,'[1]Controle Distribuição de Lucros'!$C$1:$Q$357,15)*'Lucros aos Sócios'!G35),IF(D35="Contabilidade"," ",0))) -> #N/A
A36: 61 | B36: =VLOOKUP(A36,Empresas!A:B,2,0) -> 03.338.180/0001-04 | C36: =VLOOKUP(B36,Empresas!B:C,2,0) -> Aprobato Neto Contabilidade e Apoio Empresarial Ltda | D36: =VLOOKUP(C36,'[1]Controle Distribuição de Lucros'!$C$1:$G$357,5,0) -> #N/A | E36: 269.649.348-04 | F36: João Aprobato Neto | G36: 1 | H36: =IF(D36="Contabilidade Aproximada",(VLOOKUP(C36,'Apuração Contabilidade Aproxima'!$C$1:$M$357,11,0)*G36),IF(D36="Distribuição por Presunção",(VLOOKUP(C36,'[1]Controle Distribuição de Lucros'!$C$1:$Q$357,15)*'Lucros aos Sócios'!G36),IF(D36="Contabilidade"," ",0))) -> #N/A
A37: 972 | B37: =VLOOKUP(A37,Empresas!A:B,2,0) -> 00.000.904/0001-17 | C37: =VLOOKUP(B37,Empresas!B:C,2,0) -> Aprobato Neto Perícias Técnicas Ltda | D37: =VLOOKUP(C37,'[1]Controle Distribuição de Lucros'!$C$1:$G$357,5,0) -> #N/A | E37: 269.649.348-04 | F37: João Aprobato Neto | G37: 0.825 | H37: =IF(D37="Contabilidade Aproximada",(VLOOKUP(C37,'Apuração Contabilidade Aproxima'!$C$1:$M$357,11,0)*G37),IF(D37="Distribuição por Presunção",(VLOOKUP(C37,'[1]Controle Distribuição de Lucros'!$C$1:$Q$357,15)*'Lucros aos Sócios'!G37),IF(D37="Contabilidade"," ",0))) -> #N/A
A38: 972 | B38: =VLOOKUP(A38,Empresas!A:B,2,0) -> 00.000.904/0001-17 | C38: =VLOOKUP(B38,Empresas!B:C,2,0) -> Aprobato Neto Perícias Técnicas Ltda | D38: =VLOOKUP(C38,'[1]Controle Distribuição de Lucros'!$C$1:$G$357,5,0) -> #N/A | E38: 294.594.188-05 | F38: Carina Turatti Farina Butuem | G38: 0.175 | H38: =IF(D38="Contabilidade Aproximada",(VLOOKUP(C38,'Apuração Contabilidade Aproxima'!$C$1:$M$357,11,0)*G38),IF(D38="Distribuição por Presunção",(VLOOKUP(C38,'[1]Controle Distribuição de Lucros'!$C$1:$Q$357,15)*'Lucros aos Sócios'!G38),IF(D38="Contabilidade"," ",0))) -> #N/A
A39: 440 | B39: =VLOOKUP(A39,Empresas!A:B,2,0) -> 71.912.349/0001-48 | C39: =VLOOKUP(B39,Empresas!B:C,2,0) -> Arakaki Enterprise Ltda | D39: =VLOOKUP(C39,'[1]Controle Distribuição de Lucros'!$C$1:$G$357,5,0) -> #N/A | E39: 324.904.628-06 | F39: Suzimeire Arakaki | G39: 0.5 | H39: =IF(D39="Contabilidade Aproximada",(VLOOKUP(C39,'Apuração Contabilidade Aproxima'!$C$1:$M$357,11,0)*G39),IF(D39="Distribuição por Presunção",(VLOOKUP(C39,'[1]Controle Distribuição de Lucros'!$C$1:$Q$357,15)*'Lucros aos Sócios'!G39),IF(D39="Contabilidade"," ",0))) -> #N/A
A40: 440 | B40: =VLOOKUP(A40,Empresas!A:B,2,0) -> 71.912.349/0001-48 | C40: =VLOOKUP(B40,Empresas!B:C,2,0) -> Arakaki Enterprise Ltda | D40: =VLOOKUP(C40,'[1]Controle Distribuição de Lucros'!$C$1:$G$357,5,0) -> #N/A | E40: 006.679.768-33 | F40: Arlete Mieco Tokunaga Arakaki | G40: 0.5 | H40: =IF(D40="Contabilidade Aproximada",(VLOOKUP(C40,'Apuração Contabilidade Aproxima'!$C$1:$M$357,11,0)*G40),IF(D40="Distribuição por Presunção",(VLOOKUP(C40,'[1]Controle Distribuição de Lucros'!$C$1:$Q$357,15)*'Lucros aos Sócios'!G40),IF(D40="Contabilidade"," ",0))) -> #N/A
...

Sheet Base
A1: Estado | B1: Vencimento TFE | C1: Partes Relacionadas | D1: Data | E1: Evento | F1: Tributação | G1: Usuário | H1: Envio de Documentos | I1: Dia Útil | J1: Escriturações | K1: REINF | L1: Movimentação Folha | M1: Tipo Aferição | N1: Procurações | O1: Parcelamentos Ativos
A2: Acre | B2: Janeiro | C2: Grupo Aprobato Neto | D2: 46237 | E2: Cisão | F2: Lucro Presumido | G2: Jorge | H2: E-mail | I2: 1 | J2: OK | K2: OK | L2: Folha de Pagamento | M2: Contabilidade | N2: Aprobato Neto | O2: Não
A3: Alagoas | B3: Fevereiro | C3: Grupo Croce Simões | D3: 46238 | E3: Desenquadramento | F3: Lucro Real | G3: Kamilly | H3: E-mail e Site | I3: 2 | J3: S/M | K3: S/M | L3: Pró-Labore | M3: Contabilidade Aproximada | N3: J P Cont | O3: Sim
A4: Amazonas | B4: Março | C4: Grupo Decor Adesivos | D4: 46239 | E4: Extinção | F4: MEI | G4: Luana | H4: E-mail Renata | I4: 3 | J4: N/A | K4: N/A | L4: Sem Movimento | M4: Contabilidade BPO
A5: Amapá | B5: Abril | C5: Grupo Dovil Indústria | D5: 46240 | E5: Fusão | F5: Simples Nacional | G5: Claudia | H5: Impostos Paulo | I5: 4 | J5: Saldo Credor | M5: Distribuição por Presunção
A6: Bahia | B6: Maio | C6: Grupo Fairbanks | D6: 46241 | E6: Incorporação | G6: Michele | H6: Impresso | I6: 5 | J6: Transmitida S/M | M6: Não Distribuir
A7: Ceará | B7: Junho | C7: Grupo FLM Engenharia | D7: 46244 | E7: Transferida | G7: Bruna | H7: Impresso Aprobato | I7: 6 | M7: Sem Movimento
A8: Distrito Federal | B8: Julho | C8: Grupo Gnomo Comércio | D8: 46245 | E8: Não se Aplica | G8: Paulo | H8: Site | I8: 7
A9: Espírito Santo | B9: Agosto | C9: Grupo Grax Lubrificantes | D9: 46246 | G9: Talita | H9: Site e E-mail | I9: 8
A10: Goiás | B10: Setembro | C10: Grupo GTR Financeira | D10: 46247 | G10: Dyego | H10: Site e WhatsApp | I10: 9
A11: Maranhão | B11: Outubro | C11: Grupo Hocar Comércio | D11: 46248 | G11: Dyego/Bruna | I11: 10
A12: Minas Gerais | B12: Novembro | C12: Grupo Ibel Maq | D12: 46251 | I12: 11
A13: Mato Grosso do Sul | B13: Dezembro | C13: Grupo Ici Gastronomia | D13: 46252 | I13: 12
A14: Mato Grosso | C14: Grupo Indikey Comunicação | D14: 46253
A15: Pará | C15: Grupo Induspacking Indústria | D15: 46254
A16: Paraíba | C16: Grupo Inox Conexões | D16: 46255
A17: Pernambuco | C17: Grupo J B S Inspeção | D17: 46258
A18: Piauí | C18: Grupo Korubo Expedições | D18: 46259
A19: Paraná | C19: Grupo KV Equipamentos | D19: 46260
A20: Rio de Janeiro | C20: Grupo LightPrint Indústria | D20: 46261
A21: Rio Grande do Norte | C21: Grupo Lopérgolo Aguiar | D21: 46262
A22: Rondônia | C22: Grupo Lu Lu | D22: 46265
A23: Roraima | C23: Grupo Media Portal
A24: Rio Grande do Sul | C24: Grupo Minale Brindes
A25: Santa Catarina | C25: Grupo Mobel Engenharia
A26: São Paulo | C26: Grupo Passarela Modas
A27: Sergipe | C27: Grupo Pedro Nevoeiro
A28: Tocantins | C28: Grupo Ribeiro
C29: Grupo SDJ Comercial
C30: Grupo Serralheria Cordeiro
C31: Grupo SeuChico Comércio
C32: Grupo Shuk Alimentos
C33: Grupo Signmaker Comunicação
C34: Grupo Solo Tecnologia
C35: Grupo Tavares Comércio
C36: Grupo Technology Publicidade
C37: Grupo Teles Comércio
C38: Grupo Tixe Participações
C39: Grupo Treeon Soluções
C40: Grupo Tricomix Comércio
...

Sheet Controle de Datas
A1: ID | B1: Datas
A2: 1 | B2: 46237
A3: 2 | B3: 46238
A4: 3 | B4: 46239
A5: 4 | B5: 46240
A6: 5 | B6: 46241
A7: 6 | B7: 46244
A8: 7 | B8: 46245
A9: 8 | B9: 46246
A10: 9 | B10: 46247
A11: 10 | B11: 46248

Sheet Procedimento Fechamento
A1: ID | B1: Procedimentos
A2: 1 | B2: Escriturar/Importar Notas Fiscais de Serviços
A3: 2 | B3: Escriturar/Importar Notas Fiscais de Saídas
A4: 3 | B4: Escriturar/Importar Notas Fiscais de Entradas (Com Relacionamento)
A5: 4 | B5: Escriturar/Importar Conhecimentos de Transportes Tomados
A6: 5 | B6: Gerar DANFE das Notas Fiscais de Entradas e Conferir as Escriturações (Lucro Presumido e Lucro Real)
A7: 6 | B7: Gerar DANFE dos Conhecimentos de Transportes Tomados e Conferir as Escriturações (Lucro Presumido e Lucro Real)
A8: 7 | B8: Verificar Eventuais Documentos Faltantes
A9: 8 | B9: Verificar Documentos Inutilizados no Ambiente Eletrônico da NFe
A10: 9 | B10: Verificar as Naturezas de ISS e ICMS (Se Estão Condizentes com as Operações da Empresa)
A11: 10 | B11: Verificar o Relacionamento de Produtos x Fornecedores
A12: 11 | B12: Arrumar a Referência dos Produtos e Posteriormente "Atualizar" os Produtos das Entradas e Saídas
A13: 12 | B13: Verificar os CSTs de Entradas e Saídas do ICMS e IPI
... A25: 24 | B25: Enviar os Tributos aos Clientes

Sheet Observações
A1: Código | B1: CNPJ | C1: Razão Social | D1: Usuário | E1: Observações
A2: 106 | B2: =VLOOKUP(A2,Empresas!A:B,2,0) -> 04.431.460/0001-25 | C2: =VLOOKUP(B2,Empresas!B:C,2,0) -> 04.431.460 Ramiro Duenas Aranzabal | D2: =VLOOKUP(A2,Empresas!A:J,10,0) -> Jorge
A3: 119 | B3: 27.541.980/0001-96 | C3: 4.Com Serviços Empresariais Ltda | D3: Jorge
A4: 415 | B4: 42.360.609/0001-11 | C4: 42.360.609 Dener Mendonça de Souza | D4: Jorge
A5: 218 | B5: 43.436.474/0001-93 | C5: 43.436.474 Maria Clara Tomé Garcia | D5: Jorge
A6: 628 | B6: 43.959.791/0001-94 | C6: 43.959.791 Ana Isabela Pithan Maraschin | D6: Jorge
A7: 227 | B7: 44.645.259/0001-65 | C7: 44.645.259 Rebeca Brito Cardoso | D7: Jorge
A8: 359 | B8: 04.362.429/0001-80 | C8: 4CS Serviços Ltda | D8: Paulo
A9: 638 | B9: 51.957.545/0001-21 | C9: 51.957.545 Marjorie Abdallah | D9: Bruna
A10: 437 | B10: 53.494.930/0001-05 | C10: 53.494.930 Gabriela Afonso Prado | D10: Jorge
A11: 461 | B11: 54.535.015/0001-83 | C11: Ada Maria Fraulo Pires | D11: Bruna
A12: 525 | B12: 58.344.129/0001-05 | C12: 58.344.129 Gilda Maria de Lima Roberto | D12: Jorge
A13: 608 | B13: 13.581.219/0001-73 | C13: A & V Marques Imóveis Ltda | D13: Talita
A14: 34 | B14: 22.189.167/0001-85 | C14: A Galeria Artes Presentes Jóias Design Rocym Ltda | D14: Jorge
... A22: 230 | B22: 04.746.127/0001-05 | C22: Alexandre Silva Voza | D22: Michele
A23: 370 | B23: 37.140.411/0001-92 | C23: Allora Construtora e Incorporadora Ltda | D23: Kamilly | E23: As Guias de ISSQN Serão Emitidas por Eles à Partir do Fechamento de Maio-2025
A24: 578 | B24: 13.314.231/0001-11 | C24: Alpha Entretenimento e Lazer Ltda | D24: Talita
A25: 302 | B25: 01.665.434/0001-73 | C25: Alphaville Comercial Ltda | D25: Luana
A26: 376 | B26: 09.086.104/0001-35 | C26: Américo Suriano e Companhia Ltda | D26: Michele
A27: 576 | B27: 49.343.692/0001-60 | C27: Ápice Artes Gráficas Ltda | D27: Paulo | E27: Retenções Apuradas por Competência e Tem Retenção Sobre Aluguéis. Ficar Atento a Tributação das Receitas Financeiras e Outras Receitas Para Fins de PIS e COFINS. Verificar Também os Ajustes de ICMS (i) Aquisição de Paletes com Diferimento; (ii) Aquisição de Energia Elétrica Fora do Estado; e (iii) Diferencial de Alíquota
A28: 61 | B28: 03.338.180/0001-04 | C28: Aprobato Neto Contabilidade e Apoio Empresarial Ltda | D28: Paulo
A29: 972 | B29: 00.000.904/0001-17 | C29: Aprobato Neto Perícias Técnicas Ltda | D29: Paulo | E29: Empresa Sujeita a Prestação de Serviços com Retenção de ISSQN na Fonte, Verificar os Documentos Fiscais e Aplicar a Natureza 5.933.003
A30: 972 (-2) | B30: 00.000.904/0002-06 | C30: Aprobato Neto Perícias Técnicas Ltda | D30: Paulo
A31: 440 | B31: 71.912.349/0001-48 | C31: Arakaki Enterprise Ltda | D31: Talita
A32: 18 | B32: 61.094.660/0001-73 | C32: Aramfactor Utilidades em Arames Ltda | D32: Talita | E32: Verificar as Receitas Financeiras Para Fins de Tributação do IRPJ e CSLL. Cliente Encaminha o Relatório de ICMS e IPI, em Caso de Divergência Entrar em Contato
A33: 127 | B33: 02.400.369/0001-17 | C33: Associação Brasileira de Wakeboard | D33: Jorge
A34: 208 | B34: 07.010.849/0001-95 | C34: Associação dos Serv e Magis Para Manut do Berçário do TRT da 2 Região | D34: Jorge
A35: 175 | B35: 39.563.909/0001-93 | C35: Assunção Antunes Corretora de Seguros Ltda | D35: Luana
A36: 594 | B36: 61.633.486/0001-90 | C36: Astra Tecnologia Ltda | D36: Claudia
A37: 556 | B37: 37.911.956/0001-55 | C37: Atta Participações Ltda | D37: Jorge
A38: 279 | B38: 04.914.402/0001-52 | C38: Augusta e Respeitável Loja Simbólica Paz e Harmonia | D38: Talita
A39: 615 | B39: 63.531.342/0001-58 | C39: Augusto Ferrari Gestão Patrimonial Ltda | D39: Claudia
A40: 586 | B40: 61.108.827/0001-08 | C40: Aviana Ltda | D40: Bruna
A41: 330 | B41: 00.368.304/0001-06 | C41: Avs Vital Comércio de Tecidos e Resíduos Ltda | D41: Claudia
A42: 148 | B42: 31.748.724/0001-41 | C42: B.M.M. Apoio Empresarial Ltda | D42: Jorge
A43: 512 | B43: 65.934.747/0001-62 | C43: Bar e Lanches Volta Cruzeiro Ltda | D43: Claudia
A44: 155 | B44: 32.412.497/0001-41 | C44: Benedito José da Silva 08720320868 | D44: Talita
A45: 351 | B45: 47.407.177/0001-70 | C45: Bepass S.A. | D45: Talita | E45: Empresa Optante Pelo Lucro Real Porém Apura PIS e COFINS de Forma Cumulativa. Verificar a Aplicabilidade do Diferencial de Alíquota
A46: 510 | B46: 55.769.305/0001-54 | C46: Bianca Ribeiro Mattos Ltda | D46: Claudia
A47: 646 | B47: 67.041.408/0001-82 | C47: Bitachon Serviços Administrativos Ltda | D47: Jorge
...

Sheet Empresas
A1: Código | B1: CNPJ | C1: Razão Social | D1: Tributação | E1: Inscrição Estadual | F1: Estado | G1: Inscrição Municipal | H1: Município | I1: Partes Relacionadas | J1: Usuário | K1: Eventos | L1: Envio de Documentos | M1: Dia Útil | N1: Data Limite | O1: Data Início | P1: Data Final | Q1: Status | R1: Acompanhamento | S1: Procurações | T1: Conferência
A2: 106 | B2: 04.431.460/0001-25 | C2: 04.431.460 Ramiro Duenas Aranzabal | D2: MEI | E2: 116270616110 | F2: São Paulo | G2: 3.656.245-9 | H2: São Paulo | I2: Não se Aplica | J2: Jorge | K2: Não se Aplica | L2: E-mail | M2: 3 | N2: =VLOOKUP(M2,'Controle de Datas'!A:B,2,0) -> 46239 | O2: 46239 | P2: 46239 | Q2: =IF(R2="Não Inicializada",1,IF(R2="Em Andamento",1,IF(R2="Entregue com Atraso",-1,IF(R2="Em Atraso",-1,0)))) -> 0 | R2: =IF(OR(N2="",AND(O2="",P2="")),"Não Inicializada",IF(AND(O2<=N2,P2=""),"Em Andamento",IF(P2>N2,"Entregue com Atraso",IF(O2>N2,"Em Atraso","Entregue")))) -> Entregue | S2: Aprobato Neto
A3: 119 | B3: 27.541.980/0001-96 | C3: 4.Com Serviços Empresariais Ltda | D3: Simples Nacional | E3: Isenta | F3: São Paulo | G3: 5.694.018-1 | H3: São Paulo | I3: Não se Aplica | J3: Jorge | K3: Não se Aplica | L3: Site | M3: 5 | N3: =VLOOKUP(M3,'Controle de Datas'!A:B,2,0) -> 46241 | O3: 46248 | P3: 46248 | Q3: =IF(R3="Não Inicializada",1,IF(R3="Em Andamento",1,IF(R3="Entregue com Atraso",-1,IF(R3="Em Atraso",-1,0)))) -> -1 | R3: =IF(OR(N3="",AND(O3="",P3="")),"Não Inicializada",IF(AND(O3<=N3,P3=""),"Em Andamento",IF(P3>N3,"Entregue com Atraso",IF(O3>N3,"Em Atraso","Entregue")))) -> Entregue com Atraso | S3: Aprobato Neto
A4: 415 | B4: 42.360.609/0001-11 | C4: 42.360.609 Dener Mendonça de Souza | D4: MEI | E4: Isenta | F4: São Paulo | G4: 1470672 | H4: Jundiaí | I4: Não se Aplica | J4: Jorge | K4: Não se Aplica | L4: Site | M4: 2 | N4: =VLOOKUP(M4,'Controle de Datas'!A:B,2,0) -> 46238 | O4: 46239 | P4: 46239 | Q4: =IF(R4="Não Inicializada",1,IF(R4="Em Andamento",1,IF(R4="Entregue com Atraso",-1,IF(R4="Em Atraso",-1,0)))) -> -1 | R4: =IF(OR(N4="",AND(O4="",P4="")),"Não Inicializada",IF(AND(O4<=N4,P4=""),"Em Andamento",IF(P4>N4,"Entregue com Atraso",IF(O4>N4,"Em Atraso","Entregue")))) -> Entregue com Atraso | S4: J P Cont
A5: 218 | B5: 43.436.474/0001-93 | C5: 43.436.474 Maria Clara Tomé Garcia | D5: MEI | E5: 799468637111 | F5: São Paulo | G5: 298839 | H5: São Bernardo do Campo | I5: Não se Aplica | J5: Jorge | K5: Não se Aplica | L5: Site | M5: 3 | N5: =VLOOKUP(M5,'Controle de Datas'!A:B,2,0) -> 46239 | O5: Distrato | P5: Distrato | Q5: =IF(R5="Não Inicializada",1,IF(R5="Em Andamento",1,IF(R5="Entregue com Atraso",-1,IF(R5="Em Atraso",-1,0)))) -> -1 | R5: =IF(OR(N5="",AND(O5="",P5="")),"Não Inicializada",IF(AND(O5<=N5,P5=""),"Em Andamento",IF(P5>N5,"Entregue com Atraso",IF(O5>N5,"Em Atraso","Entregue")))) -> Entregue com Atraso | S5: Aprobato Neto
A6: 628 | B6: 43.959.791/0001-94 | C6: 43.959.791 Ana Isabela Pithan Maraschin | D6: MEI | E6: 133256510113 | F6: São Paulo | G6: 7.107.342-6 | H6: São Paulo | I6: Não se Aplica | J6: Jorge | K6: Não se Aplica | L6: Site | M6: 4 | N6: =VLOOKUP(M6,'Controle de Datas'!A:B,2,0) -> 46240 | O6: 46239 | P6: 46239 | Q6: =IF(R6="Não Inicializada",1,IF(R6="Em Andamento",1,IF(R6="Entregue com Atraso",-1,IF(R6="Em Atraso",-1,0)))) -> 0 | R6: =IF(OR(N6="",AND(O6="",P6="")),"Não Inicializada",IF(AND(O6<=N6,P6=""),"Em Andamento",IF(P6>N6,"Entregue com Atraso",IF(O6>N6,"Em Atraso","Entregue")))) -> Entregue | S6: J P Cont
A7: 227 | B7: 44.645.259/0001-65 | C7: 44.645.259 Rebeca Brito Cardoso | D7: MEI | E7: Isenta | F7: São Paulo | G7: 158982 | H7: Osasco | I7: Não se Aplica | J7: Jorge | K7: Não se Aplica | L7: Site | M7: 5 | N7: =VLOOKUP(M7,'Controle de Datas'!A:B,2,0) -> 46241 | Q7: =IF(R7="Não Inicializada",1,IF(R7="Em Andamento",1,IF(R7="Entregue com Atraso",-1,IF(R7="Em Atraso",-1,0)))) -> 1 | R7: =IF(OR(N7="",AND(O7="",P7="")),"Não Inicializada",IF(AND(O7<=N7,P7=""),"Em Andamento",IF(P7>N7,"Entregue com Atraso",IF(O7>N7,"Em Atraso","Entregue")))) -> Não Inicializada | S7: Aprobato Neto
A8: 359 | B8: 04.362.429/0001-80 | C8: 4CS Serviços Ltda | D8: Simples Nacional | E8: Isenta | F8: São Paulo | G8: 3.005.100-2 | H8: São Paulo | I8: Grupo Aprobato Neto | J8: Paulo | K8: Não se Aplica | L8: Site | M8: 5 | N8: =VLOOKUP(M8,'Controle de Datas'!A:B,2,0) -> 46241 | Q8: =IF(R8="Não Inicializada",1,IF(R8="Em Andamento",1,IF(R8="Entregue com Atraso",-1,IF(R8="Em Atraso",-1,0)))) -> 1 | R8: =IF(OR(N8="",AND(O8="",P8="")),"Não Inicializada",IF(AND(O8<=N8,P8=""),"Em Andamento",IF(P8>N8,"Entregue com Atraso",IF(O8>N8,"Em Atraso","Entregue")))) -> Não Inicializada | S8: Aprobato Neto
A9: 638 | B9: 51.957.545/0001-21 | C9: 51.957.545 Marjorie Abdallah | D9: Simples Nacional | E9: Isenta | F9: São Paulo | G9: 4067310 | H9: São José do Rio Preto | I9: Não se Aplica | J9: Bruna | K9: Não se Aplica | L9: Site | M9: 3 | N9: =VLOOKUP(M9,'Controle de Datas'!A:B,2,0) -> 46239 | O9: 46237 | P9: 46238 | Q9: =IF(R9="Não Inicializada",1,IF(R9="Em Andamento",1,IF(R9="Entregue com Atraso",-1,IF(R9="Em Atraso",-1,0)))) -> 0 | R9: =IF(OR(N9="",AND(O9="",P9="")),"Não Inicializada",IF(AND(O9<=N9,P9=""),"Em Andamento",IF(P9>N9,"Entregue com Atraso",IF(O9>N9,"Em Atraso","Entregue")))) -> Entregue | S9: J P Cont
A10: 437 | B10: 53.494.930/0001-05 | C10: 53.494.930 Gabriela Afonso Prado | D10: MEI | E10: Isenta | F10: Distrito Federal | G10: 08.271.808/001-19 | H10: Brasília | I10: Não se Aplica | J10: Jorge | K10: Não se Aplica | L10: Site | M10: 1 | N10: =VLOOKUP(M10,'Controle de Datas'!A:B,2,0) -> 46237 | O10: 46239 | P10: 46239 | Q10: =IF(R10="Não Inicializada",1,IF(R10="Em Andamento",1,IF(R10="Entregue com Atraso",-1,IF(R10="Em Atraso",-1,0)))) -> -1 | R10: =IF(OR(N10="",AND(O10="",P10="")),"Não Inicializada",IF(AND(O10<=N10,P10=""),"Em Andamento",IF(P10>N10,"Entregue com Atraso",IF(O10>N10,"Em Atraso","Entregue")))) -> Entregue com Atraso | S10: J P Cont
A11: 461 | B11: 54.535.015/0001-83 | C11: Ada Maria Fraulo Pires | D11: Simples Nacional | E11: 135862064112 | F11: São Paulo | G11: 1.302.220-2 | H11: São Paulo | I11: Não se Aplica | J11: Bruna | K11: Não se Aplica | L11: Site | M11: 1 | N11: =VLOOKUP(M11,'Controle de Datas'!A:B,2,0) -> 46237 | O11: 46237 | P11: 46244 | Q11: =IF(R11="Não Inicializada",1,IF(R11="Em Andamento",1,IF(R11="Entregue com Atraso",-1,IF(R11="Em Atraso",-1,0)))) -> -1 | R11: =IF(OR(N11="",AND(O11="",P11="")),"Não Inicializada",IF(AND(O11<=N11,P11=""),"Em Andamento",IF(P11>N11,"Entregue com Atraso",IF(O11>N11,"Em Atraso","Entregue")))) -> Entregue com Atraso | S11: J P Cont
A12: 525 | B12: 58.344.129/0001-05 | C12: 58.344.129 Gilda Maria de Lima Roberto | D12: MEI | E12: 151811726114 | F12: São Paulo | G12: 1.609.138-9 | H12: São Paulo | I12: Não se Aplica | J12: Jorge | K12: Não se Aplica | L12: Site | M12: 1 | N12: =VLOOKUP(M12,'Controle de Datas'!A:B,2,0) -> 46237 | O12: 46239 | P12: 46239 | Q12: =IF(R12="Não Inicializada",1,IF(R12="Em Andamento",1,IF(R12="Entregue com Atraso",-1,IF(R12="Em Atraso",-1,0)))) -> -1 | R12: =IF(OR(N12="",AND(O12="",P12="")),"Não Inicializada",IF(AND(O12<=N12,P12=""),"Em Andamento",IF(P12>N12,"Entregue com Atraso",IF(O12>N12,"Em Atraso","Entregue")))) -> Entregue com Atraso | S12: J P Cont
A13: 608 | B13: 13.581.219/0001-73 | C13: A & V Marques Imóveis Ltda | D13: Simples Nacional | E13: Isenta | F13: São Paulo | G13: 4.285.073-8 | H13: São Paulo | I13: Não se Aplica | J13: Talita | K13: Não se Aplica | L13: Site | M13: 3 | N13: =VLOOKUP(M13,'Controle de Datas'!A:B,2,0) -> 46239 | O13: 46238 | P13: 46238 | Q13: =IF(R13="Não Inicializada",1,IF(R13="Em Andamento",1,IF(R13="Entregue com Atraso",-1,IF(R13="Em Atraso",-1,0)))) -> 0 | R13: =IF(OR(N13="",AND(O13="",P13="")),"Não Inicializada",IF(AND(O13<=N13,P13=""),"Em Andamento",IF(P13>N13,"Entregue com Atraso",IF(O13>N13,"Em Atraso","Entregue")))) -> Entregue | S13: J P Cont
A14: 34 | B14: 22.189.167/0001-85 | C14: A Galeria Artes Presentes Jóias Design Rocym Ltda | D14: Simples Nacional | E14: 128248912111 | F14: São Paulo | G14: 5.212.716-8 | H14: São Paulo | I14: Não se Aplica | J14: Jorge | K14: Não se Aplica | L14: E-mail | M14: 1 | N14: =VLOOKUP(M14,'Controle de Datas'!A:B,2,0) -> 46237 | O14: 46239 | P14: 46239 | Q14: =IF(R14="Não Inicializada",1,IF(R14="Em Andamento",1,IF(R14="Entregue com Atraso",-1,IF(R14="Em Atraso",-1,0)))) -> -1 | R14: =IF(OR(N14="",AND(O14="",P14="")),"Não Inicializada",IF(AND(O14<=N14,P14=""),"Em Andamento",IF(P14>N14,"Entregue com Atraso",IF(O14>N14,"Em Atraso","Entregue")))) -> Entregue com Atraso | S14: Aprobato Neto
A15: 523 | B15: 11.360.241/0001-68 | C15: A. de S. Cafcalas | D15: Simples Nacional | E15: Isenta | F15: São Paulo | G15: 3.994.283-0 | H15: São Paulo | I15: Não se Aplica | J15: Claudia | K15: Não se Aplica | L15: E-mail | M15: 2 | N15: =VLOOKUP(M15,'Controle de Datas'!A:B,2,0) -> 46238 | O15: 46238 | P15: 46238 | Q15: =IF(R15="Não Inicializada",1,IF(R15="Em Andamento",1,IF(R15="Entregue com Atraso",-1,IF(R15="Em Atraso",-1,0)))) -> 0 | R15: =IF(OR(N15="",AND(O15="",P15="")),"Não Inicializada",IF(AND(O15<=N15,P15=""),"Em Andamento",IF(P15>N15,"Entregue com Atraso",IF(O15>N15,"Em Atraso","Entregue")))) -> Entregue | S15: Aprobato Neto
A16: 587 | B16: 61.203.201/0001-80 | C16: A2M Ltda | D16: Lucro Presumido | E16: Isenta | F16: São Paulo | G16: 1.854.114-3 | H16: São Paulo | I16: Não se Aplica | J16: Luana | K16: Não se Aplica | L16: Site | M16: 10 | N16: =VLOOKUP(M16,'Controle de Datas'!A:B,2,0) -> 46248 | O16: 46245 | P16: 46246 | Q16: =IF(R16="Não Inicializada",1,IF(R16="Em Andamento",1,IF(R16="Entregue com Atraso",-1,IF(R16="Em Atraso",-1,0)))) -> 0 | R16: =IF(OR(N16="",AND(O16="",P16="")),"Não Inicializada",IF(AND(O16<=N16,P16=""),"Em Andamento",IF(P16>N16,"Entregue com Atraso",IF(O16>N16,"Em Atraso","Entregue")))) -> Entregue | S16: Aprobato Neto
A17: 225 | B17: 04.438.239/0001-07 | C17: AGM Representações Comerciais Ltda | D17: Lucro Presumido | E17: Isenta | F17: São Paulo | G17: 6942 | H17: Bariri | I17: Não se Aplica | J17: Talita | K17: Não se Aplica | L17: Site | M17: 2 | N17: =VLOOKUP(M17,'Controle de Datas'!A:B,2,0) -> 46238 | O17: 46237 | P17: 46237 | Q17: =IF(R17="Não Inicializada",1,IF(R17="Em Andamento",1,IF(R17="Entregue com Atraso",-1,IF(R17="Em Atraso",-1,0)))) -> 0 | R17: =IF(OR(N17="",AND(O17="",P17="")),"Não Inicializada",IF(AND(O17<=N17,P17=""),"Em Andamento",IF(P17>N17,"Entregue com Atraso",IF(O17>N17,"Em Atraso","Entregue")))) -> Entregue | S17: Aprobato Neto
A18: 572 | B18: 44.114.755/0001-92 | C18: AGR Tubos Conexões e Válvulas Ltda | D18: Simples Nacional | E18: 636583794113 | F18: São Paulo | G18: 141224 | H18: São Caetano do Sul | I18: Grupo Inox Conexões | J18: Michele | K18: Não se Aplica | L18: Site | M18: 3 | N18: =VLOOKUP(M18,'Controle de Datas'!A:B,2,0) -> 46239 | O18: 46237 | P18: 46240 | Q18: =IF(R18="Não Inicializada",1,IF(R18="Em Andamento",1,IF(R18="Entregue com Atraso",-1,IF(R18="Em Atraso",-1,0)))) -> -1 | R18: =IF(OR(N18="",AND(O18="",P18="")),"Não Inicializada",IF(AND(O18<=N18,P18=""),"Em Andamento",IF(P18>N18,"Entregue com Atraso",IF(O18>N18,"Em Atraso","Entregue")))) -> Entregue com Atraso | S18: Aprobato Neto
A19: 597 | B19: 33.023.255/0001-29 | C19: Alan W de O Lima Tecnologia da Informação | D19: Simples Nacional | E19: Isenta | F19: São Paulo | G19: 108240 | H19: São Caetano do Sul | I19: Grupo Fealtec | J19: Kamilly | K19: Não se Aplica | L19: Site | M19: 2 | N19: =VLOOKUP(M19,'Controle de Datas'!A:B,2,0) -> 46238 | O19: 46238 | P19: 46238 | Q19: =IF(R19="Não Inicializada",1,IF(R19="Em Andamento",1,IF(R19="Entregue com Atraso",-1,IF(R19="Em Atraso",-1,0)))) -> 0 | R19: =IF(OR(N19="",AND(O19="",P19="")),"Não Inicializada",IF(AND(O19<=N19,P19=""),"Em Andamento",IF(P19>N19,"Entregue com Atraso",IF(O19>N19,"Em Atraso","Entregue")))) -> Entregue | S19: Aprobato Neto
A20: 617 | B20: 58.717.889/0001-02 | C20: Ale Holding Participações e Negócios Ltda | D20: Lucro Presumido | E20: 152218550110 | F20: São Paulo | G20: 4253100 | H20: São José do Rio Preto | I20: Não se Aplica | J20: Luana | K20: Não se Aplica | L20: Site | M20: 3 | N20: =VLOOKUP(M20,'Controle de Datas'!A:B,2,0) -> 46239 | O20: 46238 | P20: 46238 | Q20: =IF(R20="Não Inicializada",1,IF(R20="Em Andamento",1,IF(R20="Entregue com Atraso",-1,IF(R20="Em Atraso",-1,0)))) -> 0 | R20: =IF(OR(N20="",AND(O20="",P20="")),"Não Inicializada",IF(AND(O20<=N20,P20=""),"Em Andamento",IF(P20>N20,"Entregue com Atraso",IF(O20>N20,"Em Atraso","Entregue")))) -> Entregue | S20: J P Cont
A21: 303 | B21: 02.864.188/0001-41 | C21: Alexandre Sgreccia | D21: Simples Nacional | E21: Isenta | F21: São Paulo | G21: 2.743.353-6 | H21: São Paulo | I21: Não se Aplica | J21: Luana | K21: Não se Aplica | L21: E-mail | M21: 5 | N21: =VLOOKUP(M21,'Controle de Datas'!A:B,2,0) -> 46241 | O21: 46241 | P21: 46241 | Q21: =IF(R21="Não Inicializada",1,IF(R21="Em Andamento",1,IF(R21="Entregue com Atraso",-1,IF(R21="Em Atraso",-1,0)))) -> 0 | R21: =IF(OR(N21="",AND(O21="",P21="")),"Não Inicializada",IF(AND(O21<=N21,P21=""),"Em Andamento",IF(P21>N21,"Entregue com Atraso",IF(O21>N21,"Em Atraso","Entregue")))) -> Entregue | S21: Aprobato Neto
A22: 230 | B22: 04.746.127/0001-05 | C22: Alexandre Silva Voza | D22: Simples Nacional | E22: 149989327117 | F22: São Paulo | G22: 3.070.085-0 | H22: São Paulo | I22: Não se Aplica | J22: Michele | K22: Não se Aplica | L22: Site | M22: 5 | N22: =VLOOKUP(M22,'Controle de Datas'!A:B,2,0) -> 46241 | O22: 46238 | P22: 46238 | Q22: =IF(R22="Não Inicializada",1,IF(R22="Em Andamento",1,IF(R22="Entregue com Atraso",-1,IF(R22="Em Atraso",-1,0)))) -> 0 | R22: =IF(OR(N22="",AND(O22="",P22="")),"Não Inicializada",IF(AND(O22<=N22,P22=""),"Em Andamento",IF(P22>N22,"Entregue com Atraso",IF(O22>N22,"Em Atraso","Entregue")))) -> Entregue | S22: Aprobato Neto
A23: 370 | B23: 37.140.411/0001-92 | C23: Allora Construtora e Incorporadora Ltda | D23: Lucro Presumido | E23: 128936605119 | F23: São Paulo | G23: 6.592.930-6 | H23: São Paulo | I23: Grupo Mobel Engenharia | J23: Kamilly | K23: Não se Aplica | L23: Site | M23: 9 | N23: =VLOOKUP(M23,'Controle de Datas'!A:B,2,0) -> 46247 | O23: 46251 | P23: 46251 | Q23: =IF(R23="Não Inicializada",1,IF(R23="Em Andamento",1,IF(R23="Entregue com Atraso",-1,IF(R23="Em Atraso",-1,0)))) -> -1 | R23: =IF(OR(N23="",AND(O23="",P23="")),"Não Inicializada",IF(AND(O23<=N23,P23=""),"Em Andamento",IF(P23>N23,"Entregue com Atraso",IF(O23>N23,"Em Atraso","Entregue")))) -> Entregue com Atraso | S23: Aprobato Neto
A24: 578 | B24: 13.314.231/0001-11 | C24: Alpha Entretenimento e Lazer Ltda | D24: Simples Nacional | E24: 403008716119 | F24: São Paulo | G24: 1.592.667-2 | H24: São Paulo | I24: Não se Aplica | J24: Talita | K24: Não se Aplica | L24: E-mail | M24: 2 | N24: =VLOOKUP(M24,'Controle de Datas'!A:B,2,0) -> 46238 | O24: 46237 | P24: 46237 | Q24: =IF(R24="Não Inicializada",1,IF(R24="Em Andamento",1,IF(R24="Entregue com Atraso",-1,IF(R24="Em Atraso",-1,0)))) -> 0 | R24: =IF(OR(N24="",AND(O24="",P24="")),"Não Inicializada",IF(AND(O24<=N24,P24=""),"Em Andamento",IF(P24>N24,"Entregue com Atraso",IF(O24>N24,"Em Atraso","Entregue")))) -> Entregue | S24: Aprobato Neto
A25: 302 | B25: 01.665.434/0001-73 | C25: Alphaville Comercial Ltda | D25: Simples Nacional | E25: 114726418111 | F25: São Paulo | G25: 2.558.561-4 | H25: São Paulo | I25: Não se Aplica | J25: Luana | K25: Não se Aplica | L25: Site | M25: 7 | N25: =VLOOKUP(M25,'Controle de Datas'!A:B,2,0) -> 46245 | O25: 46246 | P25: 46248 | Q25: =IF(R25="Não Inicializada",1,IF(R25="Em Andamento",1,IF(R25="Entregue com Atraso",-1,IF(R25="Em Atraso",-1,0)))) -> -1 | R25: =IF(OR(N25="",AND(O25="",P25="")),"Não Inicializada",IF(AND(O25<=N25,P25=""),"Em Andamento",IF(P25>N25,"Entregue com Atraso",IF(O25>N25,"Em Atraso","Entregue")))) -> Entregue com Atraso | S25: Aprobato Neto
A26: 376 | B26: 09.086.104/0001-35 | C26: Américo Suriano e Companhia Ltda | D26: Simples Nacional | E26: 149817697113 | F26: São Paulo | G26: 3.676.979-7 | H26: São Paulo | I26: Não se Aplica | J26: Michele | K26: Não se Aplica | L26: E-mail | M26: 10 | N26: =VLOOKUP(M26,'Controle de Datas'!A:B,2,0) -> 46248 | O26: 46238 | P26: 46246 | Q26: =IF(R26="Não Inicializada",1,IF(R26="Em Andamento",1,IF(R26="Entregue com Atraso",-1,IF(R26="Em Atraso",-1,0)))) -> 0 | R26: =IF(OR(N26="",AND(O26="",P26="")),"Não Inicializada",IF(AND(O26<=N26,P26=""),"Em Andamento",IF(P26>N26,"Entregue com Atraso",IF(O26>N26,"Em Atraso","Entregue")))) -> Entregue | S26: Aprobato Neto
A27: 576 | B27: 49.343.692/0001-60 | C27: Ápice Artes Gráficas Ltda | D27: Lucro Real | E27: 636070583117 | F27: São Paulo | G27: 23830 | H27: São Caetano do Sul | I27: Não se Aplica | J27: Paulo | K27: Não se Aplica | L27: E-mail | M27: 8 | N27: =VLOOKUP(M27,'Controle de Datas'!A:B,2,0) -> 46246 | Q27: =IF(R27="Não Inicializada",1,IF(R27="Em Andamento",1,IF(R27="Entregue com Atraso",-1,IF(R27="Em Atraso",-1,0)))) -> 1 | R27: =IF(OR(N27="",AND(O27="",P27="")),"Não Inicializada",IF(AND(O27<=N27,P27=""),"Em Andamento",IF(P27>N27,"Entregue com Atraso",IF(O27>N27,"Em Atraso","Entregue")))) -> Não Inicializada | S27: J P Cont
A28: 61 | B28: 03.338.180/0001-04 | C28: Aprobato Neto Contabilidade e Apoio Empresarial Ltda | D28: Simples Nacional | E28: Isenta | F28: São Paulo | G28: 2.818.201-4 | H28: São Paulo | I28: Grupo Aprobato Neto | J28: Paulo | K28: Não se Aplica | L28: E-mail | M28: 3 | N28: =VLOOKUP(M28,'Controle de Datas'!A:B,2,0) -> 46239 | Q28: =IF(R28="Não Inicializada",1,IF(R28="Em Andamento",1,IF(R28="Entregue com Atraso",-1,IF(R28="Em Atraso",-1,0)))) -> 1 | R28: =IF(OR(N28="",AND(O28="",P28="")),"Não Inicializada",IF(AND(O28<=N28,P28=""),"Em Andamento",IF(P28>N28,"Entregue com Atraso",IF(O28>N28,"Em Atraso","Entregue")))) -> Não Inicializada | S28: Aprobato Neto
A29: 972 | B29: 00.000.904/0001-17 | C29: Aprobato Neto Perícias Técnicas Ltda | D29: Simples Nacional | E29: Isenta | F29: São Paulo | G29: 2.254.918-8 | H29: São Paulo | I29: Grupo Aprobato Neto | J29: Paulo | K29: Não se Aplica | L29: E-mail | M29: 8 | N29: =VLOOKUP(M29,'Controle de Datas'!A:B,2,0) -> 46246 | Q29: =IF(R29="Não Inicializada",1,IF(R29="Em Andamento",1,IF(R29="Entregue com Atraso",-1,IF(R29="Em Atraso",-1,0)))) -> 1 | R29: =IF(OR(N29="",AND(O29="",P29="")),"Não Inicializada",IF(AND(O29<=N29,P29=""),"Em Andamento",IF(P29>N29,"Entregue com Atraso",IF(O29>N29,"Em Atraso","Entregue")))) -> Não Inicializada | S29: Aprobato Neto
A30: 972 (-2) | B30: 00.000.904/0002-06 | C30: Aprobato Neto Perícias Técnicas Ltda | D30: Simples Nacional | E30: Isenta | F30: São Paulo | H30: São Caetano do Sul | I30: Grupo Aprobato Neto | J30: Paulo | K30: Não se Aplica | L30: E-mail | M30: 8 | N30: =VLOOKUP(M30,'Controle de Datas'!A:B,2,0) -> 46246 | Q30: =IF(R30="Não Inicializada",1,IF(R30="Em Andamento",1,IF(R30="Entregue com Atraso",-1,IF(R30="Em Atraso",-1,0)))) -> 1 | R30: =IF(OR(N30="",AND(O30="",P30="")),"Não Inicializada",IF(AND(O30<=N30,P30=""),"Em Andamento",IF(P30>N30,"Entregue com Atraso",IF(O30>N30,"Em Atraso","Entregue")))) -> Não Inicializada | S30: Aprobato Neto
A31: 440 | B31: 71.912.349/0001-48 | C31: Arakaki Enterprise Ltda | D31: Lucro Presumido | E31: 135658787115 | F31: São Paulo | G31: 2.189.072-2 | H31: São Paulo | I31: Não se Aplica | J31: Talita | K31: Não se Aplica | L31: Site | M31: 10 | N31: =VLOOKUP(M31,'Controle de Datas'!A:B,2,0) -> 46248 | O31: 46247 | P31: 46247 | Q31: =IF(R31="Não Inicializada",1,IF(R31="Em Andamento",1,IF(R31="Entregue com Atraso",-1,IF(R31="Em Atraso",-1,0)))) -> 0 | R31: =IF(OR(N31="",AND(O31="",P31="")),"Não Inicializada",IF(AND(O31<=N31,P31=""),"Em Andamento",IF(P31>N31,"Entregue com Atraso",IF(O31>N31,"Em Atraso","Entregue")))) -> Entregue | S31: J P Cont
A32: 18 | B32: 61.094.660/0001-73 | C32: Aramfactor Utilidades em Arames Ltda | D32: Lucro Presumido | E32: 112425660117 | F32: São Paulo | G32: 9.663.449-9 | H32: São Paulo | I32: Não se Aplica | J32: Talita | K32: Não se Aplica | L32: Site | M32: 6 | N32: =VLOOKUP(M32,'Controle de Datas'!A:B,2,0) -> 46244 | O32: 46254 | P32: 46254 | Q32: =IF(R32="Não Inicializada",1,IF(R32="Em Andamento",1,IF(R32="Entregue com Atraso",-1,IF(R32="Em Atraso",-1,0)))) -> -1 | R32: =IF(OR(N32="",AND(O32="",P32="")),"Não Inicializada",IF(AND(O32<=N32,P32=""),"Em Andamento",IF(P32>N32,"Entregue com Atraso",IF(O32>N32,"Em Atraso","Entregue")))) -> Entregue com Atraso | S32: Aprobato Neto
A33: 127 | B33: 02.400.369/0001-17 | C33: Associação Brasileira de Wakeboard | D33: Lucro Real | E33: Isenta | F33: São Paulo | G33: 2.672.777-3 | H33: São Paulo | I33: Não se Aplica | J33: Jorge | K33: Não se Aplica | L33: Site e WhatsApp | M33: 2 | N33: =VLOOKUP(M33,'Controle de Datas'!A:B,2,0) -> 46238 | O33: 46239 | P33: 46239 | Q33: =IF(R33="Não Inicializada",1,IF(R33="Em Andamento",1,IF(R33="Entregue com Atraso",-1,IF(R33="Em Atraso",-1,0)))) -> -1 | R33: =IF(OR(N33="",AND(O33="",P33="")),"Não Inicializada",IF(AND(O33<=N33,P33=""),"Em Andamento",IF(P33>N33,"Entregue com Atraso",IF(O33>N33,"Em Atraso","Entregue")))) -> Entregue com Atraso | S33: Aprobato Neto
A34: 208 | B34: 07.010.849/0001-95 | C34: Associação dos Serv e Magis Para Manut do Berçário do TRT da 2 Região | D34: Lucro Real | E34: Isenta | F34: São Paulo | G34: 3.390.868-0 | H34: São Paulo | I34: Não se Aplica | J34: Jorge | K34: Não se Aplica | L34: E-mail | M34: 4 | N34: =VLOOKUP(M34,'Controle de Datas'!A:B,2,0) -> 46240 | O34: 46239 | P34: 46239 | Q34: =IF(R34="Não Inicializada",1,IF(R34="Em Andamento",1,IF(R34="Entregue com Atraso",-1,IF(R34="Em Atraso",-1,0)))) -> 0 | R34: =IF(OR(N34="",AND(O34="",P34="")),"Não Inicializada",IF(AND(O34<=N34,P34=""),"Em Andamento",IF(P34>N34,"Entregue com Atraso",IF(O34>N34,"Em Atraso","Entregue")))) -> Entregue | S34: Aprobato Neto
A35: 175 | B35: 39.563.909/0001-93 | C35: Assunção Antunes Corretora de Seguros Ltda | D35: Simples Nacional | E35: Isenta | F35: Minas Gerais | G35: 1.258.826/001-4 | H35: Belo Horizonte | I35: Grupo Indikey Comunicação | J35: Luana | K35: Não se Aplica | L35: Site | M35: 4 | N35: =VLOOKUP(M35,'Controle de Datas'!A:B,2,0) -> 46240 | O35: 46240 | P35: 46240 | Q35: =IF(R35="Não Inicializada",1,IF(R35="Em Andamento",1,IF(R35="Entregue com Atraso",-1,IF(R35="Em Atraso",-1,0)))) -> 0 | R35: =IF(OR(N35="",AND(O35="",P35="")),"Não Inicializada",IF(AND(O35<=N35,P35=""),"Em Andamento",IF(P35>N35,"Entregue com Atraso",IF(O35>N35,"Em Atraso","Entregue")))) -> Entregue | S35: Aprobato Neto
A36: 594 | B36: 61.633.486/0001-90 | C36: Astra Tecnologia Ltda | D36: Simples Nacional | E36: Isenta | F36: São Paulo | G36: 4.BP565-1 | H36: Barueri | I36: Não se Aplica | J36: Claudia | K36: Não se Aplica | L36: Site | M36: 5 | N36: =VLOOKUP(M36,'Controle de Datas'!A:B,2,0) -> 46241 | O36: 46241 | P36: 46241 | Q36: =IF(R36="Não Inicializada",1,IF(R36="Em Andamento",1,IF(R36="Entregue com Atraso",-1,IF(R36="Em Atraso",-1,0)))) -> 0 | R36: =IF(OR(N36="",AND(O36="",P36="")),"Não Inicializada",IF(AND(O36<=N36,P36=""),"Em Andamento",IF(P36>N36,"Entregue com Atraso",IF(O36>N36,"Em Atraso","Entregue")))) -> Entregue | S36: J P Cont
A37: 556 | B37: 37.911.956/0001-55 | C37: Atta Participações Ltda | D37: Lucro Presumido | E37: Isenta | F37: São Paulo | G37: 4996407 | H37: Barueri | I37: Grupo Tixe Participações | J37: Jorge | K37: Não se Aplica | L37: E-mail | M37: 5 | N37: =VLOOKUP(M37,'Controle de Datas'!A:B,2,0) -> 46241 | O37: 46254 | P37: 46254 | Q37: =IF(R37="Não Inicializada",1,IF(R37="Em Andamento",1,IF(R37="Entregue com Atraso",-1,IF(R37="Em Atraso",-1,0)))) -> -1 | R37: =IF(OR(N37="",AND(O37="",P37="")),"Não Inicializada",IF(AND(O37<=N37,P37=""),"Em Andamento",IF(P37>N37,"Entregue com Atraso",IF(O37>N37,"Em Atraso","Entregue")))) -> Entregue com Atraso | S37: Aprobato Neto
A38: 279 | B38: 04.914.402/0001-52 | C38: Augusta e Respeitável Loja Simbólica Paz e Harmonia | D38: Lucro Real | E38: Isenta | F38: São Paulo | G38: 3.106.378-0 | H38: São Paulo | I38: Não se Aplica | J38: Talita | K38: Não se Aplica | L38: Site | M38: 4 | N38: =VLOOKUP(M38,'Controle de Datas'!A:B,2,0) -> 46240 | O38: 46255 | P38: 46255 | Q38: =IF(R38="Não Inicializada",1,IF(R38="Em Andamento",1,IF(R38="Entregue com Atraso",-1,IF(R38="Em Atraso",-1,0)))) -> -1 | R38: =IF(OR(N38="",AND(O38="",P38="")),"Não Inicializada",IF(AND(O38<=N38,P38=""),"Em Andamento",IF(P38>N38,"Entregue com Atraso",IF(O38>N38,"Em Atraso","Entregue")))) -> Entregue com Atraso | S38: Aprobato Neto
A39: 615 | B39: 63.531.342/0001-58 | C39: Augusto Ferrari Gestão Patrimonial Ltda | D39: Lucro Presumido | E39: Isenta | F39: São Paulo | G39: 0.059.091-6 | H39: São Paulo | I39: Não se Aplica | J39: Claudia | K39: Não se Aplica | L39: Site | M39: 5 | N39: =VLOOKUP(M39,'Controle de Datas'!A:B,2,0) -> 46241 | O39: 46246 | P39: 46247 | Q39: =IF(R39="Não Inicializada",1,IF(R39="Em Andamento",1,IF(R39="Entregue com Atraso",-1,IF(R39="Em Atraso",-1,0)))) -> -1 | R39: =IF(OR(N39="",AND(O39="",P39="")),"Não Inicializada",IF(AND(O39<=N39,P39=""),"Em Andamento",IF(P39>N39,"Entregue com Atraso",IF(O39>N39,"Em Atraso","Entregue")))) -> Entregue com Atraso | S39: Aprobato Neto
A40: 586 | B40: 61.108.827/0001-08 | C40: Aviana Ltda | D40: Simples Nacional | E40: Isenta | F40: São Paulo | G40: 1.846.546-3 | H40: São Paulo | I40: Não se Aplica | J40: Bruna | K40: Não se Aplica | L40: Site | M40: 1 | N40: =VLOOKUP(M40,'Controle de Datas'!A:B,2,0) -> 46237 | O40: 46237 | P40: 46238 | Q40: =IF(R40="Não Inicializada",1,IF(R40="Em Andamento",1,IF(R40="Entregue com Atraso",-1,IF(R40="Em Atraso",-1,0)))) -> -1 | R40: =IF(OR(N40="",AND(O40="",P40="")),"Não Inicializada",IF(AND(O40<=N40,P40=""),"Em Andamento",IF(P40>N40,"Entregue com Atraso",IF(O40>N40,"Em Atraso","Entregue")))) -> Entregue com Atraso | S40: J P Cont
...

Sheet Planilha1

Sheet Municipais
A1: Código | B1: CNPJ | C1: Razão Social | D1: Tributação | E1: Usuário | F1: Município | G1: Vencimento TFE | H1: Inscrição Municipal | I1: Senha Prefeitura | J1: Vencto. ISS | K1: ISSQN | M1: Escrit. Prefeitura | N1: DSUP | O1: Imunidades SDI | P1: Declaração GBF | Q1: Parc Municipais
A2: 106 | B2: =VLOOKUP(A2,Empresas!A:B,2,0) -> 04.431.460/0001-25 | C2: =VLOOKUP(B2,Empresas!B:C,2,0) -> 04.431.460 Ramiro Duenas Aranzabal | D2: =VLOOKUP(C2,Empresas!C:D,2,0) -> MEI | E2: =VLOOKUP(A2,Empresas!A:J,10,0) -> Jorge | F2: =VLOOKUP(A2,Empresas!A:H,8,0) -> São Paulo | G2: Julho | H2: =VLOOKUP(A2,Empresas!A:G,7,0) -> 3.656.245-9 | I2: ARA217du | J2: 10 | K2: S/M | M2: S/M | N2: N/A | O2: N/A | P2: N/A | Q2: S/M
A3: 119 | B3: 27.541.980/0001-96 | C3: 4.Com Serviços Empresariais Ltda | D3: Simples Nacional | E3: Jorge | F3: São Paulo | G3: Julho | H3: 5.694.018-1 | I3: Cservicos27 | J3: 10 | K3: S/M | M3: OK | N3: N/A | O3: N/A | P3: N/A | Q3: S/M
A4: 415 | B4: 42.360.609/0001-11 | C4: 42.360.609 Dener Mendonça de Souza | D4: MEI | E4: Jorge | F4: Jundiaí | G4: Isento | H4: 1470672 | I4: W8METVGZ | J4: 25 | K4: S/M | M4: S/M | N4: N/A | O4: N/A | P4: N/A | Q4: N/A
A5: 218 | B5: 43.436.474/0001-93 | C5: 43.436.474 Maria Clara Tomé Garcia | D5: MEI | E5: Jorge | F5: São Bernardo do Campo | G5: Isento | H5: 298839 | I5: 298839UQG43441 | J5: 15 | K5: S/M | M5: S/M | N5: N/A | O5: N/A | P5: N/A | Q5: N/A
A6: 628 | B6: 43.959.791/0001-94 | C6: 43.959.791 Ana Isabela Pithan Maraschin | D6: MEI | E6: Jorge | F6: São Paulo | G6: Isento | H6: 7.107.342-6 | J6: 10 | K6: S/M | M6: S/M | N6: N/A | O6: N/A | P6: N/A | Q6: S/M
A7: 227 | B7: 44.645.259/0001-65 | C7: 44.645.259 Rebeca Brito Cardoso | D7: MEI | E7: Jorge | F7: Osasco | G7: Isento | H7: 158982 | I7: 446452Re | J7: 10 | K7: S/M | M7: OK | N7: N/A | O7: N/A | P7: N/A | Q7: N/A
A8: 359 | B8: 04.362.429/0001-80 | C8: 4CS Serviços Ltda | D8: Simples Nacional | E8: Paulo | F8: São Paulo | G8: Julho | H8: 3.005.100-2 | I8: 043624Cs | K8: S/M
A9: 638 | B9: 51.957.545/0001-21 | C9: 51.957.545 Marjorie Abdallah | D9: Simples Nacional | E9: Bruna | F9: São José do Rio Preto | G9: Abril | H9: 4067310 | I9: 51957545Ma! | J9: 17 | K9: N/A | L9: N/A | M9: OK | N9: N/A | O9: N/A | P9: N/A
A10: 437 | B10: 53.494.930/0001-05 | C10: 53.494.930 Gabriela Afonso Prado | D10: MEI | E10: Jorge | F10: Brasília | G10: Isento | H10: 08.271.808/001-19 | I10: Sucesso@22 | J10: 20 | K10: S/M | M10: S/M | N10: N/A | O10: N/A | P10: N/A | Q10: N/A
A11: 461 | B11: 54.535.015/0001-83 | C11: Ada Maria Fraulo Pires | D11: Simples Nacional | E11: Bruna | F11: São Paulo | G11: Julho | H11: 1.302.220-2 | I11: Adamaria1956@ | J11: 10 | K11: S/M | M11: S/M | N11: N/A | O11: N/A | P11: N/A | Q11: N/A
A12: 525 | B12: 58.344.129/0001-05 | C12: 58.344.129 Gilda Maria de Lima Roberto | D12: MEI | E12: Jorge | F12: São Paulo | G12: Isento | H12: 1.609.138-9 | I12: Abapai46# | J12: 10 | K12: S/M | M12: S/M | N12: N/A | O12: N/A | P12: N/A | Q12: N/A
